Workbook

Sheet Correspondencia AEEH 2026
B1: CORRESPONDENCIA EXTERNA 2026 DIRECCIÓN DE PROYECTOS E INFRAESTRUCTURA ENERGÉTICA
A2: No. | B2: NO. DE TURNO | C2: MES | D2: FECHA DE RECEPCIÓN POR LA DPIE | E2: NO. DE OFICIO | F2: No. EXPEDIENTE | G2: ASUNTO | H2: RESPONSABLE DE DAR ATENCIÓN | I2: NIVEL DE PRIORIDAD | J2: FECHA DE TURNO | K2: ¿SOLICITUD ATENDIDA? | L2: NÚMERO DE GESTIÓN EN SIGA | M2: OFICIO Y/O ACCIÓN DE RESPUESTA | N2: ¿SOLICITUD GESTIONADA ANTE CFE? | O2: GESTIONADA, MEDIANTE OFICIO | P2: ¿CFE DIO RESPUESTA? | Q2: OFICIO CON EL QUE CFE DA RESPUESTA | R2: ¿SOLICITUD GESTIONADA ANTE AYUNTAMIENTOS? | S2: GESTIONADA, MEDIANTE OFICIO | T2: ¿AYUNTAMIENTO DIO RESPUESTA? | U2: OFICIO CON EL QUE EL AYUNTMIENTO DA RESPUESTA | V2: SOLICITUD INGRESADA POR | W2: ÁREA GENERADORA | X2: CLASIFICACIÓN | Y2: MUNICIPIO | Z2: LOCALIDAD | AA2: GÉNERO | AB2: NÚMERO DE TELÉFONO | AC2: CORREO ELECTRÓNICO | AD2: PERSONAS ATENDIDAS | AE2: Beneficiarios Directos | AF2: Beneficiarios Indirectos | AG2: DIVISIONES C F E | AH2: ZONAS CFE | AI2: FIRMA DE RECIBIDO
A3: 1 | B3: 123 | C3: FEBRERO | D3: 46070 | E3: SEDECO/CGI/TI/0156/2026 SDPEE/DGAP/339/2026 | F3: AEEH-2*1S.1/01-2026 ASESORIAS EN MATERIA ENERGÉTICA (VARIOS MUNICIPIOS) | G3: ATENDER AL C. MIGUEL ALONSO HERNÁNDEZ (ANGELICA ALONSO GONZALEZ), PARA CONECTARSE A LA RED DE ENERGÍA ELÉCTRICA EN LA COMUNIDAD DE LAS NUECES, HUEJUTLA (TLANCHINOL) | H3: ING. FRANCISCO | I3: ALTO | J3: 46071 | K3: SI | L3: SDE-UCC-07902-26 | M3: AEEH/DG/152/2026, DE FECHA 23/02/2026, ENVIADO AL ING. OCTAVIO GÓMEZ PAULIN. | N3: SI | O3: AEEH/DG/0731/2026, DE FECHA 03/08/2026, ENVIADO AL ING. HUGO ALEJANDRO ABUNDIS GONZÁLEZ | P3: NO | Q3: N/A | R3: N/A | S3: N/A | T3: N/A | U3: N/A | V3: CIUDADANO (A) | W3: ATENCIÓN AL PUEBLO | X3: 6.- INFRAESTRUCTURA ELÉCTRICA | Y3: 28 HUEJUTLA DE REYES | Z3: LAS NUECES | AA3: MASCULINO | AB3: 7713663097 | AD3: 1 | AE3: =AF3/4 -> 1 | AF3: 4 | AG3: GOLFO CENTRO | AH3: ZONA HUEJUTLA
A4: 2 | B4: 149 | C4: FEBRERO | D4: 46073 | E4: SEDECO /CGI/TI/0190/2026 SDPEE/DGAP/538/2026 | F4: AEEH-2*1S.1/01-2026 ASESORIAS EN MATERIA ENERGÉTICA (VARIOS MUNICIPIOS) | G4: SOLICITA SE LE DE ATENCIÓN AL C. PEDRO MOEDANO BACA, QUIEN SOLICITA INSTALACIÓN DE UNA RED DE ALUMBRADO PÚBLICO | H4: ING. FRANCISCO | I4: ALTO | J4: 46078 | K4: SI | L4: SDE-UCC-07900-26 | M4: AEEH/DG/168/2026, DE FECHA 27/02/2026, ENVIADO AL ING. OCTAVIO GÓMEZ PAULIN. AEEH/DG/193/2026, DE FECHA 09/03/2026, ENVIADO AL ING. OCTAVIO GÓMEZ PAULIN. | N4: NO | O4: N/A | P4: N/A | Q4: N/A | R4: N/A | S4: N/A | T4: N/A | U4: N/A | V4: CIUDADANO (A) | W4: ATENCIÓN AL PUEBLO | X4: 2.- ALUMBRADO PÚBLICO | Y4: 12 ATOTONILCO EL GRANDE | Z4: SAN JOSÉ ZOQUITAL | AA4: MASCULINO | AB4: 7712067240 | AC4: gutierrezolguinm@gmail.com | AD4: 1 | AE4: =AF4/4 -> 425 | AF4: 1700 | AG4: CENTRO ORIENTE | AH4: ZONA PACHUCA
A5: 3 | B5: 225 | C5: MARZO | D5: 46092 | E5: SEDECO/CGI/TI/0297/2026 SDPEE/DGAP/1048/2026 | F5: AEEH-2*1S.1/01-2026 ASESORIAS EN MATERIA ENERGÉTICA (VARIOS MUNICIPIOS) | G5: ATENDER A LA C. TANIA SULEMA CALVA HERRERA, QUIEN SOLICITA LA AMPLIACION DE RED ELECTRICA EN SU COMUNIDAD | H5: ING. FRANCISCO | I5: ALTO | J5: 46094 | K5: SI | L5: SDE-UC-00117-26 | M5: AEEH/DG/238/2026, DE FECHA 23/03/2026, ENVIADO AL ING. OCTAVIO GÓMEZ PAULIN. AEEH/DG/278/2026, DE FECHA 31/03/2026, ENVIADO AL ING. OCTAVIO GÓMEZ PAULIN. | N5: NO | O5: N/A | P5: N/A | Q5: N/A | R5: N/A | S5: N/A | T5: N/A | U5: N/A | V5: CIUDADANO (A) | W5: ATENCIÓN AL PUEBLO | X5: 3.- ELECTRIFICACIÓN | Y5: 9 EL ARENAL | Z5: OJO DE AGUA | AA5: FEMENINO | AB5: 7714057898 | AD5: 1 | AE5: 1 | AF5: 0 | AG5: CENTRO ORIENTE | AH5: ZONA PACHUCA
A6: 4 | B6: 291 | C6: ABRIL | D6: 46119 | E6: SEDECO/CGI/TI/0408/2026 SDPEE/DGAP/1816/2026 | F6: AEEH-2*1S.1/01-2026 ASESORIAS EN MATERIA ENERGÉTICA (VARIOS MUNICIPIOS) | G6: ATENDER A LA DELEGADA GRICELDA MARTÍNEZ CHÁVEZ, QUIEN SOLICITA APOYO PARA CAMBIAR LA LINEA DE LUZ YA QUE LOS POSTES SE ENCUENTRAN EN MAL ESTADO | H6: ING. FRANCISCO | I6: ALTO | J6: 46119 | K6: SI | L6: SDE-UC-00316-26 | M6: AEEH/DG/311/2026, DE FECHA 10/04/2026, ENVIADO AL ING. OCTAVIO GÓMEZ PAULIN COORDINADOR DE GESTIÓN INSTITUCIONAL | N6: SI | O6: AEEH/DG/386/2026, DE FECHA 28/04/2026, ENVIADO AL ING. ALEJANDRO YUSULMAN HERNÁNDEZ LEAL, SUPERINTENDENTE DE CFE DISTRIBUCIÓN ZONA IXMIQUILPAN | P6: NO | Q6: N/A | R6: N/A | S6: N/A | T6: N/A | U6: N/A | V6: DELEGADO (A) MUNICIPAL | W6: ATENCIÓN AL PUEBLO | X6: 8.- MEJORAS A LA RED | Y6: 6 ALFAJAYUCAN | Z6: BOXTHÓ | AA6: FEMENINO | AB6: 7721374560 | AD6: 1 | AE6: =AF6/4 -> 30 | AF6: 120 | AG6: DIVISION BAJIO | AH6: ZONA IXMIQUILPAN
A7: 5 | B7: 068 | C7: FEBRERO | D7: 46057 | E7: S/N | F7: AEEH-2*1S.5/01-2026 ENERGIA REGIONAL | G7: ENERGIA REGIONAL SOLICITA AUDIENCIA PARA PRESENTAR LA PROPUESTA "ESTUDIO TÉCNICO JUSTIFICATIVO PARA LA INSCRIPCIÓN DE PROYECTOS DE ELECTRICIDAD EN LA PLANEACIÓN VINCULANTE" | H7: ARQ. ORLANDO | I7: ALTO | J7: 46057 | K7: SI | L7: SDE-UCC-07705-26 | M7: AEEH/DG/319/2026, DE FECHA 10/04/2026, ENVIADO AL ING. OCTAVIO GOMEZ PAULIN, COORDINADOR DE GESTÍON INSTITUCIONAL ARQ. ORLANDO SE CONECTA A LA REUNIÓN CON EL C. MIGUEL ÁNGEL HORTA MARTIN | N7: N/A | O7: N/A | P7: N/A | Q7: N/A | R7: N/A | S7: N/A | T7: N/A | U7: N/A | V7: EMPRESA PRIVADA | W7: OTRAS INSTANCIAS | X7: 7.- INVITACIONES/EXPOS/CONGRESOS/TEMAS ADMINISTRATIVOS/CAPACITACIONES/ATENCIÓN A EMPRESAS/ELECTROMOVILIDAD/OTROS | AA7: MASCULINO | AB7: 55 41 77 30 76 | AC7: miguel.horta@eregional.com.mx | AD7: 1 | AE7: 1 | AF7: 0 | AG7: N/A | AH7: N/A
A8: 6 | B8: 316 | C8: ABRIL | D8: 46125 | E8: SEDECO/CGI/TI/0450/2026 SDPEE/DGAP/2191/2026 | F8: AEEH-2*1S.1/01-2026 ASESORIAS EN MATERIA ENERGÉTICA (VARIOS MUNICIPIOS) | G8: ATENDER A PEDRO GUERRERO GONZALEZ, QUIEN SOLICITA LA AMPLIACIÓN DE LA RED DE ENERGIA ELECTRICA Y COLOCACIÓN DE 2 TRANSFORMADORES EN SU LOCALIDAD | H8: ING. FRANCISCO | I8: ALTO | J8: 46125 | K8: SI | L8: SDE-UC-00404-26 | M8: AEEH/DG/359/2026, DE FECHA 21/04/2026, ENVIADO AL ING. OCTAVIO GOMEZ PAULIN | N8: SI | O8: AEEH/DG/432/2026, DE FECHA 14/05/2026, ENVIADO AL ING. ALEJANDRO YUSULMAN HERNÁNDEZ LEAL, SUPERINTENDENTE DE LA CFE ZONA IXMIQUILPAN | P8: NO | Q8: N/A | R8: N/A | S8: N/A | T8: N/A | U8: N/A | V8: DELEGADO (A) MUNICIPAL | W8: ATENCIÓN AL PUEBLO | X8: 3.- ELECTRIFICACIÓN | Y8: 29 HUICHAPAN | Z8: JONACOPA | AA8: MASCULINO | AB8: 7731284313 | AC8: pedroguerrerogonz30@gmail.com | AD8: 1 | AE8: =AF8/4 -> 45 | AF8: 180 | AG8: DIVISION BAJIO | AH8: ZONA IXMIQUILPAN
A9: 7 | B9: 509 | C9: JUNIO | D9: 46190 | E9: SEDECO/CGI/TI/0758/2026 SDPEE/DGAP/3882/2026 | F9: AEEH-2*1S.1/01-2026 ASESORIAS EN MATERIA ENERGÉTICA (VARIOS MUNICIPIOS) | G9: ATENDER AL C. ROGELIO MORALES HERNÁNDEZ, QUIEN SOLICITA MEDIACIÓN CON CFE PARA LA REUBICACIÓN DE UN POSTE DE SU LOCALIDAD. | H9: ING. FRANCISCO | I9: ALTO | J9: 46191 | K9: SI | L9: SDE-UC-01014-26 | M9: AEEH/DG/590/2026, DE FECHA 30/06/2026, ENVIADO AL ING. OCTAVIO GÓMEZ PAULIN, COORDINADOR DE GESTIÓN INSTITUCIONAL. | N9: NO | O9: N/A | P9: N/A | Q9: N/A | V9: DELEGADO (A) MUNICIPAL | W9: ATENCIÓN AL PUEBLO | X9: 13.- REUBICACIÓN DE POSTES | Y9: 81 ZACUALTIPÁN DE ÁNGELES | Z9: SAN MIGUEL FERRERÍA | AA9: MASCULINO | AB9: 55 45 33 81 78 | AD9: 1 | AG9: GOLFO CENTRO | AH9: ZONA HUEJUTLA
A10: 8 | B10: 510 | C10: JUNIO | D10: 46190 | E10: SEDECO/CGI/TI/0759/2026 SDPEE/DGAP/3883/2026 | F10: AEEH-2*1S.1/01-2026 ASESORIAS EN MATERIA ENERGÉTICA (VARIOS MUNICIPIOS) | G10: ATENDER AL C. ROGELIO MORALES HERNÁNDEZ, QUIEN SOLICITA MEDIACIÓN CON CFE PARA LA REHABILITACIÓN DE ALUMBRADO PÚBLICO. | H10: ING. FRANCISCO | I10: ALTO | J10: 46191 | K10: SI | L10: SDE-UC-00993-26 | M10: AEEH/DG/591/2026, DE FECHA 30/06/2026, ENVIADO AL ING. OCTAVIO GÓMEZ PAULIN, COORDINADOR DE GESTIÓN INSTITUCIONAL. | N10: N/A | O10: N/A | P10: N/A | Q10: N/A | V10: DELEGADO (A) MUNICIPAL | W10: ATENCIÓN AL PUEBLO | X10: 2.- ALUMBRADO PÚBLICO | Y10: 81 ZACUALTIPÁN DE ÁNGELES | Z10: SAN MIGUEL FERRERÍA | AA10: MASCULINO | AB10: 55 45 33 81 78 | AD10: 1 | AG10: GOLFO CENTRO | AH10: ZONA HUEJUTLA
A11: 9 | B11: 511 | C11: JUNIO | D11: 46190 | E11: SEDECO/CGI/TI/0760/2026 SDPEE/DGAP/3962/2026 | F11: AEEH-2*1S.1/01-2026 ASESORIAS EN MATERIA ENERGÉTICA (VARIOS MUNICIPIOS) | G11: ATENDER A MARÍA CRISTINA PÉREZ HERNÁNDEZ, QUIEN SOLICITA MEDIACIÓN CON CFE, ANTE MULTA IMPUESTA POR CANCELACIÓN DE SERVICIO. | H11: ARQ. DIEGO | I11: ALTO | J11: 46191 | K11: SI | L11: SDE-UC-01018-26 | M11: AEEH/DG/592/2026, DE FECHA 30/06/2026, ENVIADO AL ING. OCTAVIO GÓMEZ PAULIN, COORDINADOR DE GESTIÓN INSTITUCIONAL. | N11: N/A | O11: N/A | P11: N/A | Q11: N/A | V11: CIUDADANO (A) | W11: ATENCIÓN AL PUEBLO | X11: 1.- ADEUDO | Y11: 38 MINERAL DEL CHICO | Z11: CAPULA | AA11: FEMENINO | AB11: 771 760 3516 | AD11: 1 | AG11: CENTRO ORIENTE | AH11: ZONA PACHUCA
A12: 10 | B12: 516 | C12: JUNIO | D12: 46190 | E12: SEDECO/CGI/TI/0761/2026 SDPEE/DGAP/3937/2026 | F12: AEEH-2*1S.1/01-2026 ASESORIAS EN MATERIA ENERGÉTICA (VARIOS MUNICIPIOS) | G12: ATENDER A FIDENCIA SIERRA PEREZ, QUIEN SOLICITA LA INTRODUCCIÓN DEL SERVICIO DE ENERGÍA ELÉCTRICA | H12: ING. FRANCISCO | I12: ALTO | J12: 46191 | K12: SI | L12: SDE-UC-01016-26 | M12: AEEH/DG/593/2026, DE FECHA 30/06/2026, ENVIADO AL ING. OCTAVIO GÓMEZ PAULIN, COORDINADOR DE GESTIÓN INSTITUCIONAL. | N12: N/A | O12: N/A | P12: N/A | Q12: N/A | V12: CIUDADANO (A) | W12: ATENCIÓN AL PUEBLO | X12: 3.- ELECTRIFICACIÓN | Y12: 56 SANTIAGO TULANTEPEC DE LUGO GUERRERO | Z12: ALTEPEMILA | AA12: FEMENINO | AB12: 775 260 0224 | AD12: 1 | AG12: CENTRO ORIENTE | AH12: ZONA TULANCINGO
A13: 11 | B13: 512 | C13: JUNIO | D13: 46190 | E13: SEDECO/CGI/TI/0762/2026 SDPEE/DGAP/3991/2026 | F13: AEEH-2*1S.1/01-2026 ASESORIAS EN MATERIA ENERGÉTICA (VARIOS MUNICIPIOS) | G13: ATENDER A RICARDO GRANADOS MEDINA, QUIEN SOLICITA APOYO PARA INSTALACIÓN DE ALUMBRADO PÚBLICO EN SU FRACCIONMIENTO | H13: ING. FRANCISCO | I13: ALTO | J13: 46191 | K13: SI | L13: SDE-UC-01017-26 | M13: AEEH/DG/594/2026, DE FECHA 30/06/2026, ENVIADO AL ING. OCTAVIO GÓMEZ PAULIN, COORDINADOR DE GESTIÓN INSTITUCIONAL. | N13: N/A | O13: N/A | P13: N/A | Q13: N/A | V13: CIUDADANO (A) | W13: ATENCIÓN AL PUEBLO | X13: 2.- ALUMBRADO PÚBLICO | Y13: 51 MINERAL DE LA REFORMA | Z13: PRADERAS DE VIRREYES | AA13: MASCULINO | AB13: 55 45 90 0874 | AD13: 1 | AG13: CENTRO ORIENTE | AH13: ZONA PACHUCA
A14: 12 | B14: 513 | C14: JUNIO | D14: 46190 | E14: SEDECO/CGI/TI/0763/2026 SDPEE/DGAP/3993/2026 | F14: AEEH-2*1S.1/01-2026 ASESORIAS EN MATERIA ENERGÉTICA (VARIOS MUNICIPIOS) | G14: ATENDER A JOSE SIERRA CASTELÁN, QUIEN SOLICITA LA AMPLIACIÓN DE RED ELECTRICA EN SU COMUNIDAD | H14: ING. FRANCISCO | I14: ALTO | J14: 46191 | K14: SI | L14: SDE-UC-01019-26 | M14: AEEH/DG/595/2026, DE FECHA 30/06/2026, ENVIADO AL ING. OCTAVIO GÓMEZ PAULIN, COORDINADOR DE GESTIÓN INSTITUCIONAL. | N14: N/A | O14: N/A | P14: N/A | Q14: N/A | V14: CIUDADANO (A) | W14: ATENCIÓN AL PUEBLO | X14: 3.- ELECTRIFICACIÓN | Y14: 56 SANTIAGO TULANTEPEC DE LUGO GUERRERO | Z14: COL. LOS ROMEROS | AA14: MASCULINO | AB14: 55 12 44 77 85 | AD14: 1 | AG14: CENTRO ORIENTE | AH14: ZONA TULANCINGO
A15: 13 | B15: 514 | C15: JUNIO | D15: 46190 | E15: SEDECO/CGI/TI/0764/2026 SDPEE/DGAP/3998/2026 | F15: AEEH-2*1S.1/01-2026 ASESORIAS EN MATERIA ENERGÉTICA (VARIOS MUNICIPIOS) | G15: ATENDER A LA C. EVA JAZMIN GONZÁLEZ GONZÁLEZ, QUIEN SOLICITA EL SERVICIO DE ENERGÍA ELÉCTRICA PARA 30 VIVIENDAS DE SU LOCALIDAD | H15: ING. FRANCISCO | I15: ALTO | J15: 46191 | K15: SI | L15: SDE-UC-01020-26 | M15: AEEH/DG/596/2026, DE FECHA 30/06/2026, ENVIADO AL ING. OCTAVIO GÓMEZ PAULIN, COORDINADOR DE GESTIÓN INSTITUCIONAL. | N15: N/A | O15: N/A | P15: N/A | Q15: N/A | V15: CIUDADANO (A) | W15: ATENCIÓN AL PUEBLO | X15: 3.- ELECTRIFICACIÓN | Y15: 56 SANTIAGO TULANTEPEC DE LUGO GUERRERO | Z15: SAN FRANCISCO HUATENGO | AA15: FEMENINO | AB15: 775 235 8855 | AD15: 1 | AG15: CENTRO ORIENTE | AH15: ZONA TULANCINGO
A16: 14 | B16: 515 | C16: JUNIO | D16: 46190 | E16: SEDECO/CGI/TI/0765/2026 SDPEE/DGAP/4000/2026 | F16: AEEH-2*1S.1/01-2026 ASESORIAS EN MATERIA ENERGÉTICA (VARIOS MUNICIPIOS) | G16: ATENDER A LA C. MARÍA DEL CARMEN RIVERA MARTÍNEZ, QUIEN SOLICITA LA AMPLIACIÓN DE RED DE ENERGÍA ELECTRICA EN SU LOCALIDAD | H16: ING. FRANCISCO | I16: ALTO | J16: 46191 | K16: SI | L16: SDE-UC-01021-26 | M16: AEEH/DG/597/2026, DE FECHA 30/06/2026, ENVIADO AL ING. OCTAVIO GÓMEZ PAULIN, COORDINADOR DE GESTIÓN INSTITUCIONAL. | N16: N/A | O16: N/A | P16: N/A | Q16: N/A | V16: CIUDADANO (A) | W16: ATENCIÓN AL PUEBLO | X16: 3.- ELECTRIFICACIÓN | Y16: 16 CUAUTEPEC DE HINOJOSA | Z16: TEPANTITLA | AA16: FEMENINO | AB16: 775 141 6197 | AD16: 1 | AG16: CENTRO ORIENTE | AH16: ZONA TULANCINGO
A17: 15 | B17: 386 | C17: MAYO | D17: 46149 | E17: SEDECO/CGI/0158/2026 | F17: AEEH-2*1S/08-2026 SOLICITUDES DE LA DIRECCIÓN DE ATENCIÓN AL PUEBLO | G17: INVITACIÓN PARA ASISTIR A REUNIONES TRIMETRALES CON LA DIRECCIÓN DE ATENCIÓN AL PUEBLO | H17: ARQ. ORLANDO | I17: BAJO | J17: 46149 | K17: SI | L17: SDE-CGI-00265-26 | M17: DE CONOCIMIENTO | N17: N/A | O17: N/A | P17: N/A | Q17: N/A | R17: N/A | S17: N/A | T17: N/A | U17: N/A | V17: DEPENDENCIA ESTATAL | W17: OTRAS INSTANCIAS | X17: 7.- INVITACIONES/EXPOS/CONGRESOS/TEMAS ADMINISTRATIVOS/CAPACITACIONES/ATENCIÓN A EMPRESAS/ELECTROMOVILIDAD/OTROS | AD17: 1 | AE17: 1 | AF17: 0 | AG17: N/A | AH17: N/A
A18: 16 | B18: 021 | C18: ENERO | D18: 46043 | E18: SEDECO/CGI/0013/2026 | F18: AEEH-2*1S/08-2026 SOLICITUDES DE LA DIRECCIÓN DE ATENCIÓN AL PUEBLO | G18: DESIGNAR UN ENLACE PARA EL SEGUIMIENTO Y RESOLUCIÓN DE LAS SOLICITUDES DE LA DIRECCIÓN DE ATENCIÓN AL PUEBLO | H18: LIC. ARELI | I18: BAJO | J18: 46043 | K18: SI | L18: SDE-CGI-00202-26 | M18: AEEH/DG/052/2026, DE FECHA 23/01/2026, ENVIADO AL ING. OCTAVIO GÓMEZ PAULIN, COORDINADOR DE GESTIÓN INSTITUCIONAL | N18: N/A | O18: N/A | P18: N/A | Q18: N/A | R18: N/A | S18: N/A | T18: N/A | U18: N/A | V18: DEPENDENCIA ESTATAL | W18: OTRAS INSTANCIAS | X18: 7.- INVITACIONES/EXPOS/CONGRESOS/TEMAS ADMINISTRATIVOS/CAPACITACIONES/ATENCIÓN A EMPRESAS/ELECTROMOVILIDAD/OTROS | AA18: MASCULINO | AB18: 771 688 6026 | AC18: octavio.gomez@hidalgo.gob.mx | AD18: 1 | AE18: 1 | AF18: 0 | AG18: N/A | AH18: N/A
A19: 17 | B19: 039 | C19: ENERO | D19: 46042 | E19: UPLAPH/COEMERE/013/2026 | F19: AEEH-2*1S/04-2026 MEJORA REGULATORIA | G19: LA COEMERE SOLICITA ELABORAR LA ACTUALIZACIÓN DEL CIERRE DEL PROGRAMA ANUAL DE MEJORA REGULATORIA 2025 EN LA PLATAFORMA AID-RUTS | H19: LIC. ARELI ING. FRANCISCO | I19: ALTO | J19: 46043 | K19: SI | L19: N/A | M19: AEEH/DG/055/2026, DE FECHA 26/01/2026, ENVIADO AL MTRO. ANDRÉS MANNING NOVALES, TITULAR DE LA COEMERE | N19: N/A | O19: N/A | P19: N/A | Q19: N/A | R19: N/A | S19: N/A | T19: N/A | U19: N/A | V19: DEPENDENCIA ESTATAL | W19: OTRAS INSTANCIAS | X19: 7.- INVITACIONES/EXPOS/CONGRESOS/TEMAS ADMINISTRATIVOS/CAPACITACIONES/ATENCIÓN A EMPRESAS/ELECTROMOVILIDAD/OTROS | AA19: MASCULINO | AB19: 771 715 6672 | AC19: dependencias.coemere@hidalgo.gob.mx | AD19: 1 | AE19: 1 | AF19: 0 | AG19: N/A | AH19: N/A
A20: 18 | B20: 562 | C20: JULIO | D20: 46211 | E20: CENACE/DOPS/354/2026 | F20: SANDY | G20: CENACE EMITE INVITACIÓN A PARTICIPAR EN REUNIONES DEL PROCESO DE ELABORACIÓN DEL PRONÓSTICO DE DEMANDA Y CONSUMO DE ENERGÍA ELECTRICA 2027 - 2041 | H20: ING. SANDRA | I20: ALTO | J20: 46211 | K20: SI | L20: SDE-AEEH-00406-26 | M20: AEEH/DG/0650/2026, DE FECHA 09/07/2026, ENVIADO AL ING. MAURICIO CUÉLLAR AHUMADA, SUBGERENTE DE OPERACIÓN Y DESPACHO DE LA GERENCIA DEL CENTRO NACIONAL Y ENCARGADO DE LA DIRECCIPON DE OPERACIÓN Y PLANEACIÓN DEL SISTEMA. AEEH/DG/0651/2026, DE FECHA 09/07/2026, ENVIADO AL ING. CINTHYA YARELY MEZA CORTÉS, DIRECTORA GENERAL DE LA AGENCIA DE DESARROLLO VALLE DE PLATA, DIO RESPUESTA CON TURNO 586 Y OFICIO ADVP/330/2026. AEEH/DG/0653/2026, DE FECHA 09/07/2026, ENVIADO AL MTRO. ERNESTO CADENA ACOSTA, SUBSECRETARIO DE INVERSIONES Y ECONOMÍA SECTORIAL, DIO RESPUESTA CON TURNO 587 Y OFICIO SEDECO/SIyES/109/2026. | N20: N/A | O20: N/A | P20: N/A | Q20: N/A | R20: N/A | S20: N/A | T20: N/A | U20: N/A | V20: DEPENDENCIA FEDERAL | W20: OTRAS INSTANCIAS | X20: 7.- INVITACIONES/EXPOS/CONGRESOS/TEMAS ADMINISTRATIVOS/CAPACITACIONES/ATENCIÓN A EMPRESAS/ELECTROMOVILIDAD/OTROS | AD20: 1 | AE20: 1 | AF20: 0 | AG20: N/A | AH20: N/A
A21: 19 | B21: 089 | C21: FEBRERO | D21: 46057 | E21: UPLAPH/COEMERE/105/2026 | F21: AEEH-2*1S/04-2026 MEJORA REGULATORIA | G21: DESIGNACIÓN O RATIFICACIÓN DE LOS ENLACES ANTE LA COMISIÓN DE MEJORA REGULATORIA | H21: LIC. ARELI | I21: ALTO | J21: 46057 | K21: SI | L21: N/A | M21: AEEH/DG/077/2026, DE FECHA 05/02/2026, ENVIADO AL MTRO. ANDRÉS MANNING NOVALES AEEH/DG/085-1/2026, DE FECHA 06/02/2026, ENVIADO A ARQ. ORLANDO MARTÍNEZ JUÁREZ AEEH/DG/085-2/2026, DE FECHA 06/02/2026, ENVIADO A ING. FRANCISCO JAVIER GARCÍA VILLALPA AEEH/DG/085-3/2026, DE FECHA 06/02/2026, ENVIADO A LIC. EVA BERENICE RAMÍREZ PÉREZ AEEH/DG/085-4/2026, DE FECHA 06/02/2026, ENVIADO A LIC. CARLOS LÓPEZ ESPINOSA | N21: N/A | O21: N/A | P21: N/A | Q21: N/A | R21: N/A | S21: N/A | T21: N/A | U21: N/A | V21: DEPENDENCIA ESTATAL | W21: OTRAS INSTANCIAS | X21: 7.- INVITACIONES/EXPOS/CONGRESOS/TEMAS ADMINISTRATIVOS/CAPACITACIONES/ATENCIÓN A EMPRESAS/ELECTROMOVILIDAD/OTROS | AA21: MASCULINO | AB21: 771 715 6672 | AC21: dependencias.coemere@hidalgo.gob.mx | AD21: 1 | AE21: 1 | AF21: 0 | AG21: N/A | AH21: N/A
A22: 20 | B22: 624 | C22: JULIO | D22: 46232 | E22: UPLAPH/COEMERE/236/2026 | G22: LA COMISIÓN ESTATAL DE MEJORA REGULATORIA SOLICITA REQUISITAR EL FORMATO CORRESPONDIENTE AL CENSO NACIONAL DE GOBIERNOS ESTATALES 2026, COORDINADO POR EL INEGI, EN LO REFERENTE A TRÁMITES Y SERVICIOS DE LA AGENCIA | H22: ARQ. ORLANDO LIC. ARELI | I22: ALTO | J22: 46232 | K22: SI | L22: N/A | M22: AEEH/DG/0773/2026, DE FECHA 10/08/2026, ENVIADO AL MTRO. ANDRÉS MANNING NOVALES, TITULAR DE LA COEMERE | N22: N/A | O22: N/A | P22: N/A | Q22: N/A | R22: N/A | S22: N/A | T22: N/A | U22: N/A | V22: DEPENDENCIA ESTATAL | W22: OTRAS INSTANCIAS | X22: 7.- INVITACIONES/EXPOS/CONGRESOS/TEMAS ADMINISTRATIVOS/CAPACITACIONES/ATENCIÓN A EMPRESAS/ELECTROMOVILIDAD/OTROS | AD22: 1 | AG22: N/A | AH22: N/A
A23: 21 | B23: 662 | C23: AGOSTO | D23: 46244 | E23: SEMARNATH/DESP/SSyCC/DGCC/000386/2026 | F23: AEEH-2*1S.4/07-2026 PROGRAMA ESTATAL DE ACCIÓN ANTE EL CAMBIO CLIMATICO DE HIDALGO / COMISIÓN ESTATAL INTERSECTORIAL DEL CAMBIO CLIMATICO | G23: INVITACIÓN A REUNIÓN VIRTUAL EL 12 DE AGOSTO PARA LA VALIDACIÓN DE FICHAS DEL PROGRAMA ESTATAL DE ACCIÓN ANTE EL CAMBIO CLIMATICO DEL ESTADO DE HIDALGO (PEACCH) | H23: ARQ. DIEGO | I23: MEDIO | J23: 46244 | K23: SI | L23: SDE-AEEH-00425-26 | M23: AEEH/DG/0781/2026, DE FECHA 13/08/2026, ENVIADO A LA MTRA. MONICA PATRICIA MIXTEGA TREJO, SECRETARIA DE LA SEMARNATH | N23: N/A | O23: N/A | P23: N/A | Q23: N/A | R23: N/A | S23: N/A | T23: N/A | U23: N/A | V23: DEPENDENCIA ESTATAL | W23: OTRAS INSTANCIAS | X23: 7.- INVITACIONES/EXPOS/CONGRESOS/TEMAS ADMINISTRATIVOS/CAPACITACIONES/ATENCIÓN A EMPRESAS/ELECTROMOVILIDAD/OTROS | AA23: FEMENINO | AD23: 1 | AE23: 1 | AG23: N/A | AH23: N/A
A24: 22 | B24: 658 | C24: AGOSTO | D24: 46245 | E24: SEDECO/CGI/TI/0983/2026 SDPEE/DGAP/5398/2026 | F24: DIEGO | G24: ATENDER A MARTINIANO MARTÍNEZ BAUTISTA, QUIEN SOLICITA LA AMPLIACIÓN DE LA RED DE ENERGÍA ELECTRICA (4 POSTES) | H24: ARQ. DIEGO | I24: ALTO | J24: 46245 | K24: SI | L24: SDE-UC-01506-26 | M24: AEEH/DG/0795/2026, DE FECHA 12/08/2026, ENVIADO AL ING. OCTAVIO GÓMEZ PAULIN, COORDINADOR DE GESTIÓN INSTITUCIONAL | N24: SI | O24: AEEH/DG/0832/2026, DE FECHA 18/08/2026, ENVIADO AL ING. HUGO ALEJANDRO ABUNDIS GONZALEZ, SUPERINTENDENTE DE LA COMISIÓN FEDERAL DE LECTRICIDAD ZONA HUEJUTLA | P24: N/A | Q24: N/A | V24: CIUDADANO (A) | W24: ATENCIÓN AL PUEBLO | X24: 3.- ELECTRIFICACIÓN | Y24: 14 CALNALI | AA24: MASCULINO | AD24: 1 | AE24: 1 | AG24: GOLFO CENTRO | AH24: ZONA HUEJUTLA
A25: 23 | B25: 668 | C25: AGOSTO | D25: 46245 | E25: SEDECO/CGI/TI/0992/2026 SDPEE/DGAP/5460/2026 | F25: DIEGO | G25: ATENDER A ESTANISLAO OCAÑA PEREZ, QUIEN SOLICITA APOYO PARA LA ATENCIÓN A PROBLEMÁTICA TERRITORIAL QUE IMPIDE LA AMPLIACIÓN DE RED ELECTRICA. | H25: ARQ. DIEGO | I25: ALTO | J25: 46245 | K25: SI | L25: SDE-UC-01523-26 | M25: AEEH/DG/0796/2026, DE FECHA 12/08/2026, ENVIADO AL ING. OCTAVIO GÓMEZ PAULIN, COORDINADOR DE GESTIÓN INSTITUCIONAL | N25: N/A | O25: N/A | P25: N/A | Q25: N/A | V25: CIUDADANO (A) | W25: ATENCIÓN AL PUEBLO | X25: 3.- ELECTRIFICACIÓN | Y25: 30 IXMIQUILPAN | Z25: CERRO BLANCO | AA25: MASCULINO | AD25: 1 | AE25: 1 | AG25: DIVISION BAJIO | AH25: ZONA IXMIQUILPAN
A26: 24 | B26: 023 | C26: ENERO | D26: 46045 | E26: SDG/DGAP/119/2026 SEDECO/CGI/TI/0028/2026 | F26: AEEH-2*1S.1/01-2026 ASESORIAS EN MATERIA ENERGÉTICA (VARIOS MUNICIPIOS) | G26: SOLICITA SE LE DE ATENCIÓN AL C. EDUARDO MONTES CUELLAR , QUIEN SOLICITA APOYO PARA DAR CONTINUIDAD A LA AMPLIACIÓN DE RED ELÉCTRICA DE SU CALLE | H26: ING. FRANCISCO | I26: MEDIO | J26: 46048 | K26: SI | L26: SDE-UCC-07558-26 | M26: AEEH/DG/080/2026, DE FECHA 05/02/2026, ENVIADO AL ING. OCTAVIO GÓMEZ PAULIN, COORDINADOR DE GESTIÓN INSTITUCIONAL CERRADA | N26: NO | O26: N/A | P26: N/A | Q26: N/A | R26: N/A | S26: N/A | T26: N/A | U26: N/A | V26: CIUDADANO (A) | W26: ATENCIÓN AL PUEBLO | X26: 3.- ELECTRIFICACIÓN | Y26: 58 TASQUILLO | Z26: LA NUEZ | AA26: MASCULINO | AB26: 772 119 5254 | AD26: 1 | AE26: =AF26/4 -> 26 | AF26: 104 | AG26: DIVISION BAJIO | AH26: ZONA IXMIQUILPAN
A27: 25 | B27: 635 | C27: AGOSTO | D27: 46238 | E27: SEDECO/SIyES/TI/104/2026 | F27: DIEGO | G27: SUBSECRETARIA DE INVERSIONES Y ECONOMIA SECTORIAL, SOLICITA REVISIÓN DE UGAS DE LA INDUSTRIA ENERGETICA, PARA DAR CUMPLIMIENTO AL PROGRAMA DE ORDENAMIENTO ECOLOGICO LOCAL PARTICIPATIVO( POELP) PACHUCA DE SOTO | H27: ARQ. DIEGO | I27: ALTO | J27: 46232 | K27: SI | L27: SDE-SIES-00347-26 | M27: AEEH/DG/0805/2026, DE FECHA 14/08/2026, ENVIADO AL ARQ. ERNESTO CADENA ACOSTA SUBSECRETARIO DE INVERSIONES Y ECONOMÍA SECTORIAL DE LA SECRETARÍA DE DESARROLLO ECONÓMICO (SEDECO) NO SE CARGO EN SIGA PORQUE VENCIÓ EL PERIODO, SE ENVÍO POR CORREO ELECTRÓNICO Y SE ENTREGO EN LA SUBSECRETARIA | N27: N/A | O27: N/A | P27: N/A | Q27: N/A | R27: N/A | S27: N/A | T27: N/A | U27: N/A | V27: DEPENDENCIA ESTATAL | W27: OTRAS INSTANCIAS | X27: 7.- INVITACIONES/EXPOS/CONGRESOS/TEMAS ADMINISTRATIVOS/CAPACITACIONES/ATENCIÓN A EMPRESAS/ELECTROMOVILIDAD/OTROS | AD27: 1 | AE27: 1 | AG27: N/A | AH27: N/A
A28: 26 | B28: 620 | C28: AGOSTO | D28: 46238 | E28: SEDECO/CGI/TI/0936/2026 SDPEE/DGAP/5123/2026 | F28: SANDRA | G28: ATENDER A FRANCISCO ZARATE HERNANDEZ, SOLICITA INTERVENCION CON CFE PARA LA AMPLIACION DE RED DE ENERGIA ELECTRICA EN SU LOCALIDAD. | H28: ING. SANDRA | I28: ALTO | J28: 46232 | K28: SI | L28: SDE-UC-01401-26 | M28: AEEH/DG/0809/2026, DE FECHA 14/08/2026, ENVIADO AL ING. OCTAVIO GOMEZ PAULIN, COORDINADOR DE GESTIÓN INSTICUCIONAL | N28: SI | O28: AEEH/DG/0826/2026, DE FECHA 18/08/2026, ENVIADO AL ING. HUGO ALEJANDRO ABUNDIS GONZALEZ, SUPERINTENDENTE DE LA COMISIÓN FEDERAL DE LECTRICIDAD ZONA HUEJUTLA | P28: N/A | Q28: N/A | V28: CIUDADANO (A) | W28: ATENCIÓN AL PUEBLO | X28: 3.- ELECTRIFICACIÓN | Y28: 25 HUAUTLA | Z28: ACATEPEC | AA28: MASCULINO | AD28: 1 | AE28: 1 | AG28: GOLFO CENTRO | AH28: ZONA HUEJUTLA
A29: 27 | B29: 616 | C29: AGOSTO | D29: 46238 | E29: SEDECO/CGI/TI/0930/2026 SDPEE/DGAP/5066/2026 | F29: SANDRA | G29: ATENDER A LIZBET MARILU RESENDIZ OSORIO, SOLICITA LA INTRODUCCIÓN DE ENERGIA ELECTRICA QUE BENEFICIARA A 37 VECINOS DE LA LOCALIDAD. | H29: ING. SANDRA | I29: ALTO | J29: 46232 | K29: SI | L29: SDE-UC-01377-26 | M29: AEEH/DG/0810/2026, DE FECHA 14/08/2026, ENVIADO AL ING. OCTAVIO GOMEZ PAULIN, COORDINADOR DE GESTIÓN INSTITUCIONAL. AEEH/DPIE/077/2026, DE FECHA 24/08/2026, ENVIADO A LA MAP. MARIA GUADALUPE OLGUÍN ROMERO, DIRECTORA DE ACCIONES SOCIALES PARA LA JUSTICIA ENERGÉTICA. | N29: SI | O29: AEEH/DG/0824/2026, DE FECHA 18/08/2026, ENVIADO AL ING. JOSE LUIS FRANCISCO CRAVIOTO, SUPERINTENDENTE GENERAL E.F. DE LA COMISIÓN FEDERAL DE LECTRICIDAD ZONA IXMIQUILPNA | P29: N/A | Q29: N/A | V29: CIUDADANO (A) | W29: ATENCIÓN AL PUEBLO | X29: 3.- ELECTRIFICACIÓN | Y29: 18 CHAPULHUACÁN | Z29: EL CHINILLAR | AA29: FEMENINO | AD29: 1 | AE29: 1 | AG29: DIVISION BAJIO | AH29: ZONA IXMIQUILPAN
A30: 28 | B30: 615 | C30: AGOSTO | D30: 46238 | E30: SEDECO/CGI/TI/0929/2026 SDPEE/DGAP/5044/2026 | F30: SANDRA | G30: ATENDER A FLAVIO HERNANDEZ HERNANDEZ, SOLICITA SERVICIO DE ENERGIA ELECTRICA EN SU LOCALIDAD | H30: ING. SANDRA | I30: ALTO | J30: 46232 | K30: SI | L30: SDE-UC-01369-26 | M30: AEEH/DG/0811/2026, DE FECHA 14/08/2026, ENVIADO AL ING. OCTAVIO GOMEZ PAULIN, COORDINADOR DE GESTIÓN INSTITUCIONAL. AEEH/DPIE/076/2026, DE FECHA 20/08/2026, ENVIADO A LA MAP. MARIA GUADALUPE OLGUÍN ROMERO, DIRECTORA DE ACCIONES SOCIALES PARA LA JUSTICIA ENERGÉTICA. | N30: SI | O30: AEEH/DG/0823/2026, DE FECHA 18/08/2026, ENVIADO AL ING. JOSE LUIS FRANCISCO CRAVIOTO, SUPERINTENDENTE GENERAL E.F. DE LA COMISIÓN FEDERAL DE LECTRICIDAD ZONA IXMIQUILPAN | P30: N/A | Q30: N/A | V30: CIUDADANO (A) | W30: ATENCIÓN AL PUEBLO | X30: 3.- ELECTRIFICACIÓN | Y30: 18 CHAPULHUACÁN | Z30: PUERTO DEL TAMBOR | AA30: MASCULINO | AD30: 1 | AE30: 1 | AG30: DIVISION BAJIO | AH30: ZONA IXMIQUILPAN
A31: 29 | B31: 619 | C31: AGOSTO | D31: 46238 | E31: SEDECO/CGI/TI/0935/2026 SDPEE/DGAP/5101/2026 | F31: SANDRA | G31: ATENDER A FRANCISCO ZARATE HERNANDEZ, SOLICITA ALUMBRADO PUBLICO EN CALLES CERCANAS AL CENTRO DE SALUD | H31: ING. SANDRA | I31: ALTO | J31: 46232 | K31: SI | L31: SDE-UC-01399-26 | M31: AEEH/DG/0812/2026, DE FECHA 14/08/2026, ENVIADO AL ING. OCTAVIO GOMEZ PAULIN, COORDINADOR DE GESTIÓN INSTITUCIONAL | N31: N/A | O31: N/A | P31: N/A | Q31: N/A | R31: SI | S31: AEEH/DG/0861/2026, DE FECHA 24/08/2026, ENVIADO AL ING. JORGE ALBERTO HERNANDEZ CORTÉS, PRESIDENTE MUNICIPAL DE HUAUTLA | V31: CIUDADANO (A) | W31: ATENCIÓN AL PUEBLO | X31: 2.- ALUMBRADO PÚBLICO | Y31: 25 HUAUTLA | Z31: ACATEPEC | AA31: MASCULINO | AD31: 1 | AE31: 1 | AG31: GOLFO CENTRO | AH31: ZONA HUEJUTLA
A32: 30 | B32: 656 | C32: AGOSTO | D32: 46245 | E32: SEDECO/CGI/TI/0981/2026 SDPEE/DGAP/5385/2026 | F32: SANDY | G32: ATENDER A DIANA SANCHEZ RODRIGUEZ, SOLICITA APOYO CON EL REACOMODO DE LOS CABLES DE LUZ QUE SE ENCUENTRAN CERCA DE SU DOMICILIO. | H32: ING. SANDRA | I32: ALTO | J32: 46245 | K32: SI | L32: SDE-UC-01508-26 | M32: AEEH/DG/0813/2026, DE FECHA 14/08/2026, ENVIADO AL ING. OCTAVIO GOMEZ PAULIN, COORDINADOR DE GESTIÓN INSTICUCIONAL | N32: SI | O32: AEEH/DG/0825/2026, DE FECHA 18/08/2026, ENVIADO AL ING. HUGO ALEJANDRO ABUNDIS GONZALEZ, SUPERINTENDENTE DE LA COMISIÓN FEDERAL DE LECTRICIDAD ZONA HUEJUTLA | P32: N/A | Q32: N/A | V32: CIUDADANO (A) | W32: ATENCIÓN AL PUEBLO | X32: 8.- MEJORAS A LA RED | Y32: 14 CALNALI | Z32: PEZMATLAN | AA32: FEMENINO | AD32: 1 | AE32: 1 | AG32: GOLFO CENTRO | AH32: ZONA HUEJUTLA
A33: 31 | B33: 657 | C33: AGOSTO | D33: 46245 | E33: SEDECO/CGI/TI/0982/2026 SDPEE/DGAP/5392/2026 | F33: SANDY | G33: ATENDER A ANTONIO HERNÁNDEZ HERNÁNDEZ, QUIEN SOLICITA LA AMPLIACIÓN DE RED DE ENERGÍA ELECTRICA (10 POSTES DE ENERGÍA) | H33: ING. SANDRA | I33: ALTO | J33: 46245 | K33: SI | L33: SDE-UC-01501-26 | M33: AEEH/DG/0814/2026, DE FECHA 14/08/2026, ENVIADO AL ING. OCTAVIO GOMEZ PAULIN, COORDINADOR DE GESTIÓN INSTICUCIONAL | N33: SI | O33: AEEH/DG/0827/2026, DE FECHA 18/08/2026, ENVIADO AL ING. HUGO ALEJANDRO ABUNDIS GONZALEZ, SUPERINTENDENTE DE LA COMISIÓN FEDERAL DE LECTRICIDAD ZONA HUEJUTLA | P33: N/A | Q33: N/A | V33: CIUDADANO (A) | W33: ATENCIÓN AL PUEBLO | X33: 3.- ELECTRIFICACIÓN | Y33: 73 TLANCHINOL | Z33: TOTONICAPA | AA33: MASCULINO | AD33: 1 | AE33: 1 | AG33: GOLFO CENTRO | AH33: ZONA HUEJUTLA
A34: 32 | B34: 672 | C34: AGOSTO | D34: 46246 | E34: SEDECO/CGI/TI/0999/2026 SDPEE/DGAP/5541/2026 | F34: SANDY | G34: ATENDER A ARTURO FELIX ACOSTA, SOLICITA LA INSTALACIÓN DE LAMPARAS SOLARES O CELDAS FOTOVOLTAICOS PARA ALUMBRADO DE ÁREAS RECREATIVAS DE SU LOCALIDAD | H34: ING. SANDRA | I34: ALTO | J34: 46246 | K34: SI | L34: SDE-UC-01528-26 | M34: AEEH/DG/0815/2026, DE FECHA 12/08/2026, ENVIADO AL ING. OCTAVIO GÓMEZ PAULIN, COORDINADOR DE GESTIÓN INSTITUCIONAL | N34: N/A | O34: N/A | P34: N/A | Q34: N/A | X34: 2.- ALUMBRADO PÚBLICO | Y34: 14 CALNALI | Z34: COYULA | AG34: GOLFO CENTRO | AH34: ZONA HUEJUTLA
A35: 33 | B35: 673 | C35: AGOSTO | D35: 46246 | E35: SEDECO/CGI/TI/1002/2026 SDPEE/DGAP/5570/2026 | F35: SANDY | G35: ATENDER A WILEVALDO NAJERA TORRES, QUIEN SOLICITA LA INTERVENCIÓN CON CFE TRAS UN AJUSTE DE FACTURACIÓN (MULTA POR $66,523.00) | H35: ING. SANDRA | I35: ALTO | J35: 46246 | K35: SI | L35: SDE-UC-01529-26 | M35: AEEH/DG/0816/2026, DE FECHA 14/08/2026, ENVIADO AL ING. OCTAVIO GÓMEZ PAULIN, COORDINADOR DE GESTIÓN INSTITUCIONAL | N35: SI | O35: AEEH/DG/0830/2026, DE FECHA 18/08/2026, ENVIADO AL ING. RAFAEL NAVARRO PÉREZ, SUPERINTENDENTE DE LA COMISIÓN FEDERAL DE LECTRICIDAD ZONA PACHUCA | P35: SI | Q35: RNP-335-2026 | R35: N/A | S35: N/A | T35: N/A | U35: N/A | X35: 1.- ADEUDO | Y35: 52 SAN AGUSTÍN TLAXIACA
A36: 34 | B36: 697 | C36: AGOSTO | D36: 46253 | E36: SEDECO/CGI/TI/1032/2026 SDPEE/DGAP/5763/2026 | F36: DIEGO | G36: ATENDER A FILIBERTO HILARIO MOEDANO, QUIEN SOLICITA ALUMBRADO PÚBLICO EN SU LOCALIDAD | H36: ARQ. DIEGO | I36: ALTO | J36: 46254 | K36: SI | L36: SDE-UC-01596-26 | M36: AEEH/DG/0845/2026, DE FECHA 20/08/2026, ENVIADO AL ING. OCTAVIO GÓMEZ PAULIN, COORDINADOR DE GESTIÓN INSTITUCIONAL | N36: N/A | O36: N/A | P36: N/A | Q36: N/A | R36: N/A | S36: N/A | T36: N/A | U36: N/A | V36: CIUDADANO (A) | W36: ATENCIÓN AL PUEBLO | X36: 2.- ALUMBRADO PÚBLICO | Y36: 81 ZACUALTIPÁN DE ÁNGELES | AA36: MASCULINO | AD36: 1 | AG36: GOLFO CENTRO | AH36: ZONA HUEJUTLA
A37: 35 | B37: 696 | C37: AGOSTO | D37: 46253 | E37: SEDECO/CGI/TI/1033/2026 SDPEE/DGAP/5697/2026 | F37: DIEGO | G37: ATENDER A JUAN LOPEZ TELLEZ, QUIEN SOLICITA LA MODERNIZACIÓN Y REUBICACIÓN DE LA RED ELECTRICA DE SU LOCALIDAD | H37: ARQ. DIEGO | I37: ALTO | J37: 46254 | K37: SI | L37: SDE-UC-01593-26 | M37: AEEH/DG/0850/2026, DE FECHA 21/08/2026, ENVIADO AL ING. OCTAVIO GÓMEZ PAULIN, COORDINADOR DE GESTIÓN INSTITUCIONAL | N37: N/A | O37: N/A | P37: N/A | Q37: N/A | R37: N/A | S37: N/A | T37: N/A | U37: N/A | V37: CIUDADANO (A) | W37: ATENCIÓN AL PUEBLO | X37: 8.- MEJORAS A LA RED | Y37: 37 METZTITLÁN | AA37: FEMENINO | AD37: 1 | AG37: GOLFO CENTRO | AH37: ZONA HUEJUTLA
A38: 36 | B38: 693 | C38: AGOSTO | D38: 46253 | E38: SEDECO/CGI/TI/1029/2026 SDPEE/DGAP/5713/2026 | F38: DIEGO | G38: ATENDER A ARACELI CORTES SONI, QUIEN SOLICITA ALUMBRADO PÚBLICO PARA SU LOCALIDAD. | H38: ARQ. DIEGO | I38: ALTO | J38: 46254 | K38: SI | L38: SDE-UC-01594-26 | M38: AEEH/DG/0851/2026, DE FECHA 21/08/2026, ENVIADO AL ING. OCTAVIO GÓMEZ PAULIN, COORDINADOR DE GESTIÓN INSTITUCIONAL | N38: N/A | O38: N/A | P38: N/A | Q38: N/A | R38: N/A | S38: N/A | T38: N/A | U38: N/A | V38: CIUDADANO (A) | W38: ATENCIÓN AL PUEBLO | X38: 2.- ALUMBRADO PÚBLICO | Y38: 79 XOCHICOATLÁN | AA38: FEMENINO | AD38: 1 | AG38: GOLFO CENTRO | AH38: ZONA HUEJUTLA
A39: 37 | B39: 687 | C39: AGOSTO | D39: 46253 | E39: SEDECO/CGI/TI/1015/2026 SDPEE/DGAP/5602/2026 | F39: SANDY | G39: ATENDER A JOSE FELIPE JIMÉNEZ VIVEROS, QUIEN SOLICITA LA REUBICACIÓN DE UN POSTE EL CUAL ES PELIGROSO PARA LOS HABITANTES DE SU DOMICILIO. | H39: ING. SANDRA | I39: ALTO | J39: 46254 | K39: SI | L39: SDE-UC-01551-26 | M39: AEEH/DG/0856/2026, DE FECHA 24/08/2026, ENVIADO AL ING. OCTAVIO GÓMEZ PAULIN, COORDINADOR DE GESTIÓN INSTITUCIONAL | N39: N/A | O39: N/A | P39: N/A | Q39: N/A | R39: N/A | S39: N/A | T39: N/A | U39: N/A | V39: CIUDADANO (A) | W39: ATENCIÓN AL PUEBLO | X39: 13.- REUBICACIÓN DE POSTES | Y39: 48 PACHUCA DE SOTO | AA39: MASCULINO | AD39: 1 | AG39: CENTRO ORIENTE | AH39: ZONA PACHUCA
A40: 38 | B40: 694 | C40: AGOSTO | D40: 46253 | E40: SEDECO/CGI/TI/1030/2026 SDPEE/DGAP/5721/2026 | F40: SANDY | G40: ATENDER A VIRGINIA BAÑOS ISLAS, QUIEN SOLICITA MEDIACIÓN CON CFE POR UN PRESUNTO ADEUDO. | H40: ING. SANDRA | I40: ALTO | J40: 46254 | K40: SI | L40: SDE-UC-01591-26 | M40: AEEH/DG/0857/2026, DE FECHA 24/08/2026, ENVIADO AL ING. OCTAVIO GÓMEZ PAULIN, COORDINADOR DE GESTIÓN INSTITUCIONAL | N40: N/A | O40: N/A | P40: N/A | Q40: N/A | R40: N/A | S40: N/A | T40: N/A | U40: N/A | V40: CIUDADANO (A) | W40: ATENCIÓN AL PUEBLO | X40: 1.- ADEUDO | Y40: 48 PACHUCA DE SOTO | AA40: FEMENINO | AD40: 1 | AG40: CENTRO ORIENTE | AH40: ZONA PACHUCA
...

Sheet Clasificaciones
A1: RESPONSABLE DE DAR ATENCIÓN | B1: No. DE SOLICITUDES | D1: ¿SOLICITUD ATENDIDA? | E1: NO. DE OFICIO | G1: SOLICITUD INGRESADA POR | H1: TOTAL DE SOLICITUDES | J1: ATENCIÓN AL PUEBLO | K1: TOTAL DE SOLICITUDES | M1: CLASIFICACIONES DE SOLICITUDES DE LA AEEH | N1: No. | P1: MUNICIPIOS TOTALES | Q1: MUNICIPIOS CON SOLICITUD | R1: MUNICIPIOS SIN SOLICITUD | T1: MUNICIPIO | U1: TOTAL DE SOLICITUDES POR MUNICIPIO | W1: Mes de solicitud | X1: Total de solicitudes | Z1: beneficiarios indirectos | AA1: Total de beneficiarios por mes | AC1: GÉNERO | AD1: TOTAL DE SOLICITUDES
A2: ARQ. ORLANDO | B2: =COUNTIF('Correspondencia AEEH 2026'!$H$3:$H$1048576,Clasificaciones!A2) -> 38 | D2: SI | E2: =COUNTIF('Correspondencia AEEH 2026'!$K$3:$K$1048576,Clasificaciones!D2) -> 282 | G2: AYUNTAMIENTO | H2: =COUNTIF('Correspondencia AEEH 2026'!$K$3:$V$1048576,Clasificaciones!G2) -> 8 | J2: SI | K2: =COUNTIF('Correspondencia AEEH 2026'!$W$3:$W$1048576,Clasificaciones!J2) -> 0 | M2: 1.- ADEUDO | N2: =COUNTIF('Correspondencia AEEH 2026'!$X$3:$X$1048576,Clasificaciones!M2) -> 8 | P2: =COUNTA(T2:T87) -> 84 | Q2: =COUNTIF(T2:U87, ">0") -> 62 | R2: =COUNTIF(T2:U87, 0) -> 22 | T2: 1 ACATLÁN | U2: =COUNTIF('Correspondencia AEEH 2026'!$Y$3:$Y$1048576,Clasificaciones!T2) -> 0 | W2: ENERO | X2: =COUNTIF('Correspondencia AEEH 2026'!$C$3:$C$1048576,Clasificaciones!W2) -> 6 | Z2: ENERO | AA2: =SUMIF('Correspondencia AEEH 2026'!C:C,Clasificaciones!Z2,'Correspondencia AEEH 2026'!AF:AF) -> 708 | AC2: MASCULINO | AD2: =COUNTIF('Correspondencia AEEH 2026'!$AA$3:$AA$1048576,Clasificaciones!AC2) -> 123
A3: ARQ. ORLANDO ING. FRANCISCO | B3: =COUNTIF('Correspondencia AEEH 2026'!$H$3:$H$1048576,Clasificaciones!A3) -> 0 | D3: NO | E3: =COUNTIF('Correspondencia AEEH 2026'!$K$3:$K$1048576,Clasificaciones!D3) -> 0 | G3: CIUDADANO (A) | H3: =COUNTIF('Correspondencia AEEH 2026'!$K$3:$V$1048576,Clasificaciones!G3) -> 128 | J3: NO | K3: =COUNTIF('Correspondencia AEEH 2026'!$W$3:$W$1048576,Clasificaciones!J3) -> 0 | M3: 2.- ALUMBRADO PÚBLICO | N3: =COUNTIF('Correspondencia AEEH 2026'!$X$3:$X$1048576,Clasificaciones!M3) -> 47 | T3: 2 ACAXOCHITLÁN | U3: =COUNTIF('Correspondencia AEEH 2026'!$Y$3:$Y$1048576,Clasificaciones!T3) -> 4 | W3: FEBRERO | X3: =COUNTIF('Correspondencia AEEH 2026'!$C$3:$C$1048576,Clasificaciones!W3) -> 42 | Z3: FEBRERO | AA3: =SUMIF('Correspondencia AEEH 2026'!C:C,Clasificaciones!Z3,'Correspondencia AEEH 2026'!AF:AF) -> 2767 | AC3: FEMENINO | AD3: =COUNTIF('Correspondencia AEEH 2026'!$AA$3:$AA$1048576,Clasificaciones!AC3) -> 63
A4: ING. FRANCISCO | B4: =COUNTIF('Correspondencia AEEH 2026'!$H$3:$H$1048576,Clasificaciones!A4) -> 123 | D4: EN PROCESO | E4: =COUNTIF('Correspondencia AEEH 2026'!$K$3:$K$1048576,Clasificaciones!D4) -> 15 | G4: DELEGADO (A) MUNICIPAL | H4: =COUNTIF('Correspondencia AEEH 2026'!$K$3:$V$1048576,Clasificaciones!G4) -> 28 | J4: TOTAL | K4: =SUM(K2:K3) -> 0 | M4: 3.- ELECTRIFICACIÓN | N4: =COUNTIF('Correspondencia AEEH 2026'!$X$3:$X$1048576,Clasificaciones!M4) -> 58 | T4: 3 ACTOPAN | U4: =COUNTIF('Correspondencia AEEH 2026'!$Y$3:$Y$1048576,Clasificaciones!T4) -> 1 | W4: MARZO | X4: =COUNTIF('Correspondencia AEEH 2026'!$C$3:$C$1048576,Clasificaciones!W4) -> 37 | Z4: MARZO | AA4: =SUMIF('Correspondencia AEEH 2026'!C:C,Clasificaciones!Z4,'Correspondencia AEEH 2026'!AF:AF) -> 4624 | AC4: MASCULINO | AD4: =COUNTIF('Correspondencia AEEH 2026'!$AA$3:$AA$1048576,Clasificaciones!AC4) -> 123
A5: ARQ. ORLANDO ARQ. DIEGO | B5: =COUNTIF('Correspondencia AEEH 2026'!$H$3:$H$1048576,Clasificaciones!A5) -> 8 | D5: TOTAL | E5: =SUM(E2:E4) -> 297 | G5: DEPENDENCIA ESTATAL | H5: =COUNTIF('Correspondencia AEEH 2026'!$K$3:$V$1048576,Clasificaciones!G5) -> 72 | M5: 4.- ENERGÍA RENOVABLE (SOLAR, EÓLICA) | N5: =COUNTIF('Correspondencia AEEH 2026'!$X$3:$X$1048576,Clasificaciones!M5) -> 9 | T5: 4 AGUA BLANCA DE ITURBIDE | U5: =COUNTIF('Correspondencia AEEH 2026'!$Y$3:$Y$1048576,Clasificaciones!T5) -> 1 | W5: ABRIL | X5: =COUNTIF('Correspondencia AEEH 2026'!$C$3:$C$1048576,Clasificaciones!W5) -> 37 | Z5: ABRIL | AA5: =SUMIF('Correspondencia AEEH 2026'!C:C,Clasificaciones!Z5,'Correspondencia AEEH 2026'!AF:AF) -> 2696 | AC5: TOTAL | AD5: =SUM(AD3:AD4) -> 186
A6: ARQ. DIEGO | B6: =COUNTIF('Correspondencia AEEH 2026'!$H$3:$H$1048576,Clasificaciones!A6) -> 54 | G6: DEPENDENCIA FEDERAL | H6: =COUNTIF('Correspondencia AEEH 2026'!$K$3:$V$1048576,Clasificaciones!G6) -> 49 | M6: 5.- HIDROCARBUROS | N6: =COUNTIF('Correspondencia AEEH 2026'!$X$3:$X$1048576,Clasificaciones!M6) -> 0 | T6: 5 AJACUBA | U6: =COUNTIF('Correspondencia AEEH 2026'!$Y$3:$Y$1048576,Clasificaciones!T6) -> 4 | W6: MAYO | X6: =COUNTIF('Correspondencia AEEH 2026'!$C$3:$C$1048576,Clasificaciones!W6) -> 36 | Z6: MAYO | AA6: =SUMIF('Correspondencia AEEH 2026'!C:C,Clasificaciones!Z6,'Correspondencia AEEH 2026'!AF:AF) -> 2434
A7: ARQ. ORLANDO ING. FRANCISCO ARQ. DIEGO | B7: =COUNTIF('Correspondencia AEEH 2026'!$H$3:$H$1048576,Clasificaciones!A7) -> 0 | G7: EMPRESA PRIVADA | H7: =COUNTIF('Correspondencia AEEH 2026'!$K$3:$V$1048576,Clasificaciones!G7) -> 7 | M7: 6.- INFRAESTRUCTURA ELÉCTRICA | N7: =COUNTIF('Correspondencia AEEH 2026'!$X$3:$X$1048576,Clasificaciones!M7) -> 5 | T7: 6 ALFAJAYUCAN | U7: =COUNTIF('Correspondencia AEEH 2026'!$Y$3:$Y$1048576,Clasificaciones!T7) -> 4 | W7: JUNIO | X7: =COUNTIF('Correspondencia AEEH 2026'!$C$3:$C$1048576,Clasificaciones!W7) -> 45 | Z7: JUNIO | AA7: =SUMIF('Correspondencia AEEH 2026'!C:C,Clasificaciones!Z7,'Correspondencia AEEH 2026'!AF:AF) -> 0
A8: ING. FRANCISCO ARQ. DIEGO | B8: =COUNTIF('Correspondencia AEEH 2026'!$H$3:$H$1048576,Clasificaciones!A8) -> 0 | G8: INSTITUCIÓN EDUCATIVA | H8: =COUNTIF('Correspondencia AEEH 2026'!$K$3:$V$1048576,Clasificaciones!G8) -> 0 | M8: 7.- INVITACIONES/EXPOS/CONGRESOS/TEMAS ADMINISTRATIVOS/CAPACITACIONES/ATENCIÓN A EMPRESAS/ELECTROMOVILIDAD/OTROS | N8: =COUNTIF('Correspondencia AEEH 2026'!$X$3:$X$1048576,Clasificaciones!M8) -> 100 | T8: 7 ALMOLOYA | U8: =COUNTIF('Correspondencia AEEH 2026'!$Y$3:$Y$1048576,Clasificaciones!T8) -> 2 | W8: JULIO | X8: =COUNTIF('Correspondencia AEEH 2026'!$C$3:$C$1048576,Clasificaciones!W8) -> 31 | Z8: JULIO | AA8: =SUMIF('Correspondencia AEEH 2026'!C:C,Clasificaciones!Z8,'Correspondencia AEEH 2026'!AF:AF) -> 1
A9: ING. SANDRA | B9: =COUNTIF('Correspondencia AEEH 2026'!$H$3:$H$1048576,Clasificaciones!A9) -> 45 | G9: TOTAL | H9: =SUM(H2:H8) -> 292 | M9: 8.- MEJORAS A LA RED | N9: =COUNTIF('Correspondencia AEEH 2026'!$X$3:$X$1048576,Clasificaciones!M9) -> 25 | T9: 8 APAN | U9: =COUNTIF('Correspondencia AEEH 2026'!$Y$3:$Y$1048576,Clasificaciones!T9) -> 2 | W9: AGOSTO | X9: =COUNTIF('Correspondencia AEEH 2026'!$C$3:$C$1048576,Clasificaciones!W9) -> 51 | Z9: AGOSTO | AA9: =SUMIF('Correspondencia AEEH 2026'!C:C,Clasificaciones!Z9,'Correspondencia AEEH 2026'!AF:AF) -> 0
A10: LIC. ARELI | B10: =COUNTIF('Correspondencia AEEH 2026'!$H$3:$H$1048576,Clasificaciones!A10) -> 14 | M10: 9.- SISTEMAS DE BOMBEO DE AGUA POTABLE | N10: =COUNTIF('Correspondencia AEEH 2026'!$X$3:$X$1048576,Clasificaciones!M10) -> 0 | T10: 9 EL ARENAL | U10: =COUNTIF('Correspondencia AEEH 2026'!$Y$3:$Y$1048576,Clasificaciones!T10) -> 3 | W10: SEPTIEMBRE | X10: =COUNTIF('Correspondencia AEEH 2026'!$C$3:$C$1048576,Clasificaciones!W10) -> 12 | Z10: SEPTIEMBRE | AA10: =SUMIF('Correspondencia AEEH 2026'!C:C,Clasificaciones!Z10,'Correspondencia AEEH 2026'!AF:AF) -> 0
A11: LIC. ARELI ING. FRANCISCO | B11: =COUNTIF('Correspondencia AEEH 2026'!$H$3:$H$1048576,Clasificaciones!A11) -> 2 | M11: 10.- SISTEMAS DE BOMBEO PARA RIEGO AGRICOLA | N11: =COUNTIF('Correspondencia AEEH 2026'!$X$3:$X$1048576,Clasificaciones!M11) -> 0 | T11: 10 ATITALAQUIA | U11: =COUNTIF('Correspondencia AEEH 2026'!$Y$3:$Y$1048576,Clasificaciones!T11) -> 0 | W11: OCTUBRE | X11: =COUNTIF('Correspondencia AEEH 2026'!$C$3:$C$1048576,Clasificaciones!W11) -> 0 | Z11: OCTUBRE | AA11: =SUMIF('Correspondencia AEEH 2026'!C:C,Clasificaciones!Z11,'Correspondencia AEEH 2026'!AF:AF) -> 0
A12: ING. FRANCISCO ING. SANDRA | B12: =COUNTIF('Correspondencia AEEH 2026'!$H$3:$H$1048576,Clasificaciones!A12) -> 0 | M12: 11.- TELECOMUNICACIONES | N12: =COUNTIF('Correspondencia AEEH 2026'!$X$3:$X$1048576,Clasificaciones!M12) -> 2 | T12: 11 ATLAPEXCO | U12: =COUNTIF('Correspondencia AEEH 2026'!$Y$3:$Y$1048576,Clasificaciones!T12) -> 2 | W12: NOVIEMBRE | X12: =COUNTIF('Correspondencia AEEH 2026'!$C$3:$C$1048576,Clasificaciones!W12) -> 0 | Z12: NOVIEMBRE | AA12: =SUMIF('Correspondencia AEEH 2026'!C:C,Clasificaciones!Z12,'Correspondencia AEEH 2026'!AF:AF) -> 0
A13: ARQ. ORLANDO ING. SANDRA | B13: =COUNTIF('Correspondencia AEEH 2026'!$H$3:$H$1048576,Clasificaciones!A13) -> 6 | M13: 12.- SEGUIMIENTO A SOLICITUDES | N13: =COUNTIF('Correspondencia AEEH 2026'!$X$3:$X$1048576,Clasificaciones!M13) -> 33 | T13: 12 ATOTONILCO EL GRANDE | U13: =COUNTIF('Correspondencia AEEH 2026'!$Y$3:$Y$1048576,Clasificaciones!T13) -> 2 | W13: DICIEMBRE | X13: =COUNTIF('Correspondencia AEEH 2026'!$C$3:$C$1048576,Clasificaciones!W13) -> 0 | Z13: DICIEMBRE | AA13: =SUMIF('Correspondencia AEEH 2026'!C:C,Clasificaciones!Z13,'Correspondencia AEEH 2026'!AF:AF) -> 0
A14: ARQ. DIEGO ING. SANDRA | B14: =COUNTIF('Correspondencia AEEH 2026'!$H$3:$H$1048576,Clasificaciones!A14) -> 1 | M14: 13.- REUBICACIÓN DE POSTES | N14: =COUNTIF('Correspondencia AEEH 2026'!$X$3:$X$1048576,Clasificaciones!M14) -> 9 | T14: 13 ATOTONILCO DE TULA | U14: =COUNTIF('Correspondencia AEEH 2026'!$Y$3:$Y$1048576,Clasificaciones!T14) -> 1
A15: LIC. ARELI ING. SANDRA | B15: =COUNTIF('Correspondencia AEEH 2026'!$H$3:$H$1048576,Clasificaciones!A15) -> 1 | M15: 14.- CONCILIACIÓN ANTE CFE | N15: =COUNTIF('Correspondencia AEEH 2026'!$X$3:$X$1048576,Clasificaciones!M15) -> 1 | T15: 14 CALNALI | U15: =COUNTIF('Correspondencia AEEH 2026'!$Y$3:$Y$1048576,Clasificaciones!T15) -> 5
A16: ARQ. ORLANDO LIC. ARELI | B16: =COUNTIF('Correspondencia AEEH 2026'!$H$3:$H$1048576,Clasificaciones!A16) -> 2 | M16: TOTAL | N16: =SUM(N2:N14) -> 296 | T16: 15 CARDONAL | U16: =COUNTIF('Correspondencia AEEH 2026'!$Y$3:$Y$1048576,Clasificaciones!T16) -> 1
A17: ARQ. ORLANDO LIC. ARELI ING. SANDRA ARQ. DIEGO | B17: =COUNTIF('Correspondencia AEEH 2026'!$H$3:$H$1048576,Clasificaciones!A17) -> 2
A18: ARQ. ORLANDO ING. SANDRA ARQ. DIEGO | B18: =COUNTIF('Correspondencia AEEH 2026'!$H$3:$H$1048576,Clasificaciones!A18) -> 1
A19: TOTAL | B19: =SUM(B2:B16) -> 294 | T19: 16 CUAUTEPEC DE HINOJOSA | U19: =COUNTIF('Correspondencia AEEH 2026'!$Y$3:$Y$1048576,Clasificaciones!T19) -> 10 | W19: TOTAL | X19: =SUM(X2:X13) -> 297 | Z19: TOTALES | AA19: =SUM(AA2:AA13) -> 13230
T20: 17 CHAPANTONGO | U20: =COUNTIF('Correspondencia AEEH 2026'!$Y$3:$Y$1048576,Clasificaciones!T20) -> 4
T21: 18 CHAPULHUACÁN | U21: =COUNTIF('Correspondencia AEEH 2026'!$Y$3:$Y$1048576,Clasificaciones!T21) -> 3
T22: 19 CHILCUAUTLA | U22: =COUNTIF('Correspondencia AEEH 2026'!$Y$3:$Y$1048576,Clasificaciones!T22) -> 3
T23: 20 ELOXOCHITLÁN | U23: =COUNTIF('Correspondencia AEEH 2026'!$Y$3:$Y$1048576,Clasificaciones!T23) -> 1 | W23: Etiquetas de fila | X23: Cuenta de TIPO DE SOLICITUD
T24: 21 EMILIANO ZAPATA | U24: =COUNTIF('Correspondencia AEEH 2026'!$Y$3:$Y$1048576,Clasificaciones!T24) -> 1 | W24: SI | X24: 199
T25: 22 EPAZOYUCAN | U25: =COUNTIF('Correspondencia AEEH 2026'!$Y$3:$Y$1048576,Clasificaciones!T25) -> 2 | W25: 1 ELECTRIFICACIÓN | X25: 66
T26: 23 FRANCISCO I. MADERO | U26: =COUNTIF('Correspondencia AEEH 2026'!$Y$3:$Y$1048576,Clasificaciones!T26) -> 1 | W26: 10 SISTEMA FOTOVOLTAICO AISLADO | X26: 1
T27: 24 HUASCA DE OCAMPO | U27: =COUNTIF('Correspondencia AEEH 2026'!$Y$3:$Y$1048576,Clasificaciones!T27) -> 1 | W27: 11 ALTOS COSTOS Y ADEUDOS | X27: 14
T28: 25 HUAUTLA | U28: =COUNTIF('Correspondencia AEEH 2026'!$Y$3:$Y$1048576,Clasificaciones!T28) -> 5 | W28: 12 REUBICACIÓN DE POSTE | X28: 21
T29: 26 HUAZALINGO | U29: =COUNTIF('Correspondencia AEEH 2026'!$Y$3:$Y$1048576,Clasificaciones!T29) -> 0 | W29: 13 RIEGO AGRICOLA | X29: 2
T30: 27 HUEHUETLA | U30: =COUNTIF('Correspondencia AEEH 2026'!$Y$3:$Y$1048576,Clasificaciones!T30) -> 0 | W30: 14 ADMTVO./PERSONAL | X30: 1
T31: 28 HUEJUTLA DE REYES | U31: =COUNTIF('Correspondencia AEEH 2026'!$Y$3:$Y$1048576,Clasificaciones!T31) -> 3 | W31: 2 ALUMBRADO PÚBLICO | X31: 26
T32: 29 HUICHAPAN | U32: =COUNTIF('Correspondencia AEEH 2026'!$Y$3:$Y$1048576,Clasificaciones!T32) -> 10 | W32: 3 TELECOMUNICACIONES | X32: 10
T33: 30 IXMIQUILPAN | U33: =COUNTIF('Correspondencia AEEH 2026'!$Y$3:$Y$1048576,Clasificaciones!T33) -> 2 | W33: 5 EFICIENCIA ENERGÉTICA | X33: 1
T34: 31 JACALA DE LEDEZMA | U34: =COUNTIF('Correspondencia AEEH 2026'!$Y$3:$Y$1048576,Clasificaciones!T34) -> 1 | W34: 6 ENERGÍAS RENOVABLES | X34: 5
T35: 32 JALTOCÁN | U35: =COUNTIF('Correspondencia AEEH 2026'!$Y$3:$Y$1048576,Clasificaciones!T35) -> 0 | W35: 7 INFRAESTRUCTURA ELÉCTRICA | X35: 13
... T38: 35 METEPEC | U38: =COUNTIF('Correspondencia AEEH 2026'!$Y$3:$Y$1048576,Clasificaciones!T38) -> 3 | W38: Total general | X38: 199
T39: 36 SAN AGUSTÍN METZQUITITLÁN | U39: =COUNTIF('Correspondencia AEEH 2026'!$Y$3:$Y$1048576,Clasificaciones!T39) -> 0
T40: 37 METZTITLÁN | U40: =COUNTIF('Correspondencia AEEH 2026'!$Y$3:$Y$1048576,Clasificaciones!T40) -> 2
T41: 38 MINERAL DEL CHICO | U41: =COUNTIF('Correspondencia AEEH 2026'!$Y$3:$Y$1048576,Clasificaciones!T41) -> 1
T42: 39 MINERAL DEL MONTE | U42: =COUNTIF('Correspondencia AEEH 2026'!$Y$3:$Y$1048576,Clasificaciones!T42) -> 0
...

Sheet INDICADORES
A2: MES | B2: (Todas) | D2: Oficios Ingresados | E2: Atención al Pueblo | G2: Otras Instancias (Federales, Estatales y Municipales) | I2: Seguimiento a solicitudes | L2: Clasificación Total de Correspondencia | O2: No. De solicitudes
E3: Solicitudes Atendidas | F3: Solicitudes en Proceso | G3: Solicitudes Atendidas | H3: Solicitudes en Proceso | L3: 1.- ADEUDO | O3: =Clasificaciones!N2 -> 8 | V3: Municipios con solicitudes | W3: Municipios Hgo | X3: Municipios con solicitud | Y3: Municipios sin solicitud | AB3: Mes de atención | AC3: Número de mujeres directas atendidas | AD3: Número de hombres directos atendidos
A4: Etiquetas de fila | D4: =GETPIVOTDATA("No. DE TURNO",$A$2) -> #REF! | E4: =GETPIVOTDATA("No. DE TURNO",$A$2,"¿SOLICITUD ATENDIDA?","SI","ÁREA GENERADORA ","ATENCIÓN AL PUEBLO") -> #REF! | F4: =GETPIVOTDATA("No. DE TURNO",$A$2,"¿SOLICITUD ATENDIDA?","EN PROCESO","ÁREA GENERADORA ","ATENCIÓN AL PUEBLO") -> #REF! | G4: =GETPIVOTDATA("No. DE TURNO",$A$2,"¿SOLICITUD ATENDIDA?","SI","ÁREA GENERADORA ","OTRAS INSTANCIAS") -> #REF! | H4: 0 | I4: =GETPIVOTDATA("No. DE TURNO",$A$2,"ÁREA GENERADORA ","SEGUIMIENTO A SOLICITUDES") -> #REF! | L4: 2.- ALUMBRADO PÚBLICO | O4: =Clasificaciones!N3 -> 47 | W4: =Clasificaciones!P2 -> 84 | X4: =Clasificaciones!Q2 -> 62 | Y4: =Clasificaciones!R2 -> 22 | AB4: ENERO | AC4: =GETPIVOTDATA("PERSONAS ATENDIDAS",$AB$19,"MES","ENERO","GÉNERO ","FEMENINO ") -> 3 | AD4: =GETPIVOTDATA("PERSONAS ATENDIDAS",$AB$19,"MES","ENERO","GÉNERO ","MASCULINO ") -> 3
A5: ATENCIÓN AL PUEBLO | L5: 3.- ELECTRIFICACIÓN | O5: =Clasificaciones!N4 -> 58 | AB5: FEBRERO | AC5: =GETPIVOTDATA("PERSONAS ATENDIDAS",$AB$19,"MES","FEBRERO","GÉNERO ","FEMENINO ") -> 9 | AD5: =GETPIVOTDATA("PERSONAS ATENDIDAS",$AB$19,"MES","FEBRERO","GÉNERO ","MASCULINO ") -> 23
A6: SI | L6: 4.- ENERGÍA RENOVABLE (SOLAR, EÓLICA) | O6: =Clasificaciones!N5 -> 9 | AB6: MARZO | AC6: =GETPIVOTDATA("PERSONAS ATENDIDAS",$AB$19,"MES","MARZO","GÉNERO ","FEMENINO ") -> 13 | AD6: =GETPIVOTDATA("PERSONAS ATENDIDAS",$AB$19,"MES","MARZO","GÉNERO ","MASCULINO ") -> 22
A7: OTRAS INSTANCIAS | L7: 5.- HIDROCARBUROS | O7: =Clasificaciones!N6 -> 0 | AB7: ABRIL | AC7: =GETPIVOTDATA("PERSONAS ATENDIDAS",$AB$19,"MES","ABRIL","GÉNERO ","FEMENINO ") -> 9 | AD7: =GETPIVOTDATA("PERSONAS ATENDIDAS",$AB$19,"MES","ABRIL","GÉNERO ","MASCULINO ") -> 15
A8: SI | L8: 6.- INFRAESTRUCTURA ELÉCTRICA | O8: =Clasificaciones!N7 -> 5 | AB8: MAYO | AC8: =GETPIVOTDATA("PERSONAS ATENDIDAS",$AB$19,"MES","MAYO","GÉNERO ","FEMENINO ") -> 4 | AD8: =GETPIVOTDATA("PERSONAS ATENDIDAS",$AB$19,"MES","MAYO","GÉNERO ","MASCULINO ") -> 10
A9: SEGUIMIENTO A SOLICITUDES | L9: 7.- INVITACIONES/EXPOS/CONGRESOS/TEMAS ADMINISTRATIVOS/CAPACITACIONES/ATENCIÓN A EMPRESAS/ELECTROMOVILIDAD/OTROS | O9: =Clasificaciones!N8 -> 100 | AB9: JUNIO | AC9: =Clasificaciones!AU8 -> 0 | AD9: =Clasificaciones!AV8 -> 0
A10: SI | L10: 8.- MEJORAS A LA RED | O10: =Clasificaciones!N9 -> 25 | AB10: JULIO | AC10: =Clasificaciones!AU9 -> 0 | AD10: =Clasificaciones!AV9 -> 0
A11: (en blanco) | L11: 9.- SISTEMAS DE BOMBEO DE AGUA POTABLE | O11: =Clasificaciones!N10 -> 0 | AB11: AGOSTO | AC11: =Clasificaciones!AU10 -> 0 | AD11: =Clasificaciones!AV10 -> 0
A12: SI | L12: 10.- SISTEMAS DE BOMBEO PARA RIEGO AGRICOLA | O12: =Clasificaciones!N11 -> 0 | AB12: SEPTIEMBRE | AC12: =Clasificaciones!AU11 -> 0 | AD12: =Clasificaciones!AV11 -> 0
A13: Total general | L13: 11.- TELECOMUNICACIONES | O13: =Clasificaciones!N12 -> 2 | AB13: OCTUBRE | AC13: =Clasificaciones!AU12 -> 0 | AD13: =Clasificaciones!AV12 -> 0
L14: 12.- SEGUIMIENTO A SOLICITUDES | O14: =Clasificaciones!N13 -> 33 | AB14: NOVIEMBRE | AC14: =Clasificaciones!AU13 -> 0 | AD14: =Clasificaciones!AV13 -> 0
L15: 13.- REUBICACIÓN DE POSTES | O15: =Clasificaciones!N14 -> 9 | AB15: DICIEMBRE | AC15: =Clasificaciones!AU19 -> 0 | AD15: =Clasificaciones!AV19 -> 0
L16: TOTAL | O16: =SUM(O3:O15) -> 296 | AB16: TOTALES | AC16: =SUM(AC4:AC15) -> 38 | AD16: =SUM(AD4:AD15) -> 73
R17: ÁREA GENERADORA | S17: ATENCIÓN AL PUEBLO
L18: Clasificación de Correspondencia turnada por la Dirección de Atención al Pueblo | O18: No. De solicitudes | R18: MES | S18: (Todas)
L19: 1.- ADEUDO | O19: =GETPIVOTDATA("No. DE TURNO",$R$20,"CLASIFICACIÓN ","1.- ADEUDO ") -> #REF! | AB19: Suma de Personas Atendidas | AC19: Etiquetas de columna
L20: 2.- ALUMBRADO PÚBLICO | O20: =GETPIVOTDATA("No. DE TURNO",$R$20,"CLASIFICACIÓN ","2.- ALUMBRADO PÚBLICO") -> #REF! | R20: Etiquetas de fila | AB20: Etiquetas de fila | AC20: FEMENINO | AD20: MASCULINO | AE20: (en blanco) | AF20: Total general
L21: 3.- ELECTRIFICACIÓN | O21: =GETPIVOTDATA("No. DE TURNO",$R$20,"CLASIFICACIÓN ","3.- ELECTRIFICACIÓN") -> #REF! | R21: 1.- ADEUDO | AB21: ENERO | AC21: 3 | AD21: 3 | AF21: 6
L22: 4.- ENERGÍA RENOVABLE (SOLAR, EÓLICA) | O22: =GETPIVOTDATA("No. DE TURNO",$R$20,"CLASIFICACIÓN ","4.- ENERGÍA RENOVABLE (SOLAR, EÓLICA)") -> #REF! | R22: 2.- ALUMBRADO PÚBLICO | AB22: FEBRERO | AC22: 9 | AD22: 23 | AE22: 0 | AF22: 32
L23: 6.- INFRAESTRUCTURA ELÉCTRICA | O23: =GETPIVOTDATA("No. DE TURNO",$R$20,"CLASIFICACIÓN ","6.- INFRAESTRUCTURA ELÉCTRICA") -> #REF! | R23: 7.- INVITACIONES/EXPOS/CONGRESOS/TEMAS ADMINISTRATIVOS/CAPACITACIONES/ATENCIÓN A EMPRESAS/ELECTROMOVILIDAD/OTROS | AB23: MARZO | AC23: 13 | AD23: 22 | AE23: 2 | AF23: 37
L24: 7.- INVITACIONES/EXPOS/CONGRESOS/TEMAS ADMINISTRATIVOS/CAPACITACIONES/ATENCIÓN A EMPRESAS/ELECTROMOVILIDAD/OTROS | O24: =GETPIVOTDATA("No. DE TURNO",$R$20,"CLASIFICACIÓN ","7.- INVITACIONES/EXPOS/CONGRESOS/TEMAS ADMINISTRATIVOS/CAPACITACIONES/ATENCIÓN A EMPRESAS/ELECTROMOVILIDAD/OTROS ") -> #REF! | R24: 8.- MEJORAS A LA RED | AB24: ABRIL | AC24: 9 | AD24: 15 | AE24: 1 | AF24: 25
L25: 8.- MEJORAS A LA RED | O25: =GETPIVOTDATA("No. DE TURNO",$R$20,"CLASIFICACIÓN ","8.- MEJORAS A LA RED") -> #REF! | R25: 3.- ELECTRIFICACIÓN | AB25: MAYO | AC25: 4 | AD25: 10 | AE25: 6 | AF25: 20
L26: 13.- REUBICACIÓN DE POSTES | O26: =GETPIVOTDATA("No. DE TURNO",$R$20,"CLASIFICACIÓN ","13.- REUBICACIÓN DE POSTES ") -> #REF! | R26: 4.- ENERGÍA RENOVABLE (SOLAR, EÓLICA) | V26: Municipio | W26: Total de Solicitudes por Municipio | AB26: (en blanco)
L27: TOTAL | O27: =SUM(O19:O26) -> #REF! | R27: 6.- INFRAESTRUCTURA ELÉCTRICA | V27: 2 ACAXOCHITLÁN | W27: 4 | AB27: Total general | AC27: 38 | AD27: 73 | AE27: 9 | AF27: 120
R28: 13.- REUBICACIÓN DE POSTES | V28: 3 ACTOPAN | W28: 1
R29: 14.- CONCILIACIÓN ANTE CFE | V29: 4 AGUA BLANCA DE ITURBIDE | W29: 1
R30: Total general | V30: 6 ALFAJAYUCAN | W30: 4 | AB30: Mes de atención | AC30: Número de mujeres indirectas atendidas | AD30: Número de hombres indirectos atendidos
R31: ÁREA GENERADORA | S31: OTRAS INSTANCIAS | V31: 8 APAN | W31: 1 | AB31: ENERO | AC31: =GETPIVOTDATA("Beneficiarios Indirectos",$AB$45,"MES","ENERO","GÉNERO ","FEMENINO ") -> 604 | AD31: =GETPIVOTDATA("Beneficiarios Indirectos",$AB$45,"MES","ENERO","GÉNERO ","MASCULINO ") -> 104
L32: Clasificación de Correspondencia turnada por Otras Instancias (Federales, Estatales y Municipales) | O32: No. De solicitudes | R32: MES | S32: (Todas) | V32: 9 EL ARENAL | W32: 2 | AB32: FEBRERO | AC32: =GETPIVOTDATA("Beneficiarios Indirectos",$AB$45,"MES","FEBRERO","GÉNERO ","FEMENINO ") -> 355 | AD32: =GETPIVOTDATA("Beneficiarios Indirectos",$AB$45,"MES","FEBRERO","GÉNERO ","MASCULINO ") -> 2412
L33: 2.- ALUMBRADO PÚBLICO | O33: =GETPIVOTDATA("No. DE TURNO",$R$34,"CLASIFICACIÓN ","2.- ALUMBRADO PÚBLICO") -> #REF! | V33: 11 ATLAPEXCO | W33: 2 | AB33: MARZO | AC33: =GETPIVOTDATA("Beneficiarios Indirectos",$AB$45,"MES","MARZO","GÉNERO ","FEMENINO ") -> 402 | AD33: =GETPIVOTDATA("Beneficiarios Indirectos",$AB$45,"MES","MARZO","GÉNERO ","MASCULINO ") -> 4222
L34: 3.- ELECTRIFICACIÓN | O34: =GETPIVOTDATA("No. DE TURNO",$R$34,"CLASIFICACIÓN ","3.- ELECTRIFICACIÓN") -> #REF! | R34: Etiquetas de fila | V34: 12 ATOTONILCO EL GRANDE | W34: 2 | AB34: ABRIL | AC34: =GETPIVOTDATA("Beneficiarios Indirectos",$AB$45,"MES","ABRIL","GÉNERO ","FEMENINO ") -> 1692 | AD34: =GETPIVOTDATA("Beneficiarios Indirectos",$AB$45,"MES","ABRIL","GÉNERO ","MASCULINO ") -> 1004
L35: 7.- INVITACIONES/EXPOS/CONGRESOS/TEMAS ADMINISTRATIVOS/CAPACITACIONES/ATENCIÓN A EMPRESAS/ELECTROMOVILIDAD/OTROS | O35: =GETPIVOTDATA("No. DE TURNO",$R$34,"CLASIFICACIÓN ","7.- INVITACIONES/EXPOS/CONGRESOS/TEMAS ADMINISTRATIVOS/CAPACITACIONES/ATENCIÓN A EMPRESAS/ELECTROMOVILIDAD/OTROS ") -> #REF! | R35: 2.- ALUMBRADO PÚBLICO | V35: 13 ATOTONILCO DE TULA | W35: 1 | AB35: MAYO | AC35: =GETPIVOTDATA("Beneficiarios Indirectos",$AB$45,"MES","MAYO","GÉNERO ","FEMENINO ") -> 4 | AD35: =GETPIVOTDATA("Beneficiarios Indirectos",$AB$45,"MES","MAYO","GÉNERO ","MASCULINO ") -> 2430
L36: TOTAL | O36: =SUM(O33:O35) -> #REF! | R36: 7.- INVITACIONES/EXPOS/CONGRESOS/TEMAS ADMINISTRATIVOS/CAPACITACIONES/ATENCIÓN A EMPRESAS/ELECTROMOVILIDAD/OTROS | V36: 14 CALNALI | W36: 2 | AB36: JUNIO | AC36: =Clasificaciones!AU37 -> 0 | AD36: =Clasificaciones!AV37 -> 0
R37: Total general | V37: 17 CHAPANTONGO | W37: 4 | AB37: JULIO | AC37: =Clasificaciones!AU38 -> 0 | AD37: =Clasificaciones!AV38 -> 0
V38: 18 CHAPULHUACÁN | W38: 1 | AB38: AGOSTO | AC38: =Clasificaciones!AU39 -> 0 | AD38: =Clasificaciones!AV39 -> 0
V39: 20 ELOXOCHITLÁN | W39: 1 | AB39: SEPTIEMBRE | AC39: =Clasificaciones!AU40 -> 0 | AD39: =Clasificaciones!AV40 -> 0
V40: 22 EPAZOYUCAN | W40: 2 | AB40: OCTUBRE | AC40: =Clasificaciones!AU41 -> 0 | AD40: =Clasificaciones!AV41 -> 0
R41: MES | S41: (Todas) | V41: 24 HUASCA DE OCAMPO | W41: 1 | AB41: NOVIEMBRE | AC41: =Clasificaciones!AU42 -> 0 | AD41: =Clasificaciones!AV42 -> 0
...

Sheet Formato Correspondencia
A1: CONTROL EXTERNO DE CORRESPONDECIA DPIE 2026
A2: No. de Tarjeta y/o No. oficio | B2: No. de Turno | C2: Fecha de Turno Recepción AEEH | D2: Fecha de Recibido por la DPIE | E2: Vo.Bo. Director | F2: A s u n t o / Peticionario | G2: TURNADO A | H2: NIVEL DE PRIORIDAD | I2: FIRMA Y FECHA DE QUIEN RECIBE
